Workbook

Sheet 갠트 차트 템플릿
B2: WBS
B4: 프로젝트 이름 | D4: GrowPath | I4: 공휴일 · 기간/바 제외
B5: 프로젝트 관리자 | D5: 송지섭 | I5: 46300 | J5: 개천절 대체공휴일
B6: 최신화 | D6: 46303 | I6: 46304 | J6: 한글날
B7: 입력: 시작일·마감일 / 완료율은 0–100 정수 (100=완료) | I7: 예정 일정 | L7: 완료 구간 | V7: ◆ 중간 발표 | AU7: ◆ 최종 발표
B8: WBS 번호 | C8: 작업명 | D8: 작업 담당자 | E8: 시작일 | F8: 마감일 | G8: 기간 (영업일) | H8: 완료율 (0–100%) | I8: 1단계: 프로젝트 기획 및 데이터 기반 구축 | X8: 2단계: 핵심 기능 개발 및 서비스 고도화 | AM8: 3단계: 비교 검증 및 최종 서비스 배포
I9: 1주차 · 9/28–10/2 | N9: 2주차 · 10/5–10/9 | S9: 3주차 · 10/12–10/16 | X9: 4주차 · 10/19–10/23 | AC9: 5주차 · 10/26–10/30 | AH9: 6주차 · 11/2–11/6 | AM9: 7주차 · 11/9–11/13 | AR9: 8주차 · 11/16–11/20
I10: 46293 | J10: 46294 | K10: 46295 | L10: 46296 | M10: 46297 | N10: 46300 | O10: 46301 | P10: 46302 | Q10: 46303 | R10: 46304 | S10: 46307 | T10: 46308 | U10: 46309 | V10: 46310 | W10: 46311 | X10: 46314 | Y10: 46315 | Z10: 46316 | AA10: 46317 | AB10: 46318 | AC10: 46321 | AD10: 46322 | AE10: 46323 | AF10: 46324 | AG10: 46325 | AH10: 46328 | AI10: 46329 | AJ10: 46330 | AK10: 46331 | AL10: 46332 | AM10: 46335 | AN10: 46336 | AO10: 46337 | AP10: 46338 | AQ10: 46339 | AR10: 46342 | AS10: 46343 | AT10: 46344 | AU10: 46345 | AV10: 46346
B11: 1 | C11: 프로젝트 구상 및 착수 | D11: - | E11: 46293 | F11: 46303 | G11: =IF(OR(E11="",F11=""),"",IF(F11<E11,"날짜 확인",NETWORKDAYS(E11,F11,$I$5:$I$6))) -> 8 | H11: =AVERAGE(H12:H16) -> 100
B12: 1 | C12: 주제 확정 후 재기획 및 아키텍처 보완 | D12: 송지섭 | E12: 46293 | F12: 46303 | G12: =IF(OR(E12="",F12=""),"",IF(F12<E12,"날짜 확인",NETWORKDAYS(E12,F12,$I$5:$I$6))) -> 8 | H12: 100
B13: 1.1 | C13: 도로공사서비스 규정 및 평가표 분석 | D13: 신가을 | E13: 46293 | F13: 46296 | G13: =IF(OR(E13="",F13=""),"",IF(F13<E13,"날짜 확인",NETWORKDAYS(E13,F13,$I$5:$I$6))) -> 4 | H13: 100
B14: 1.2 | C14: 요구사항 정의서 및 WBS 작성 | D14: 오호민 | E14: 46296 | F14: 46297 | G14: =IF(OR(E14="",F14=""),"",IF(F14<E14,"날짜 확인",NETWORKDAYS(E14,F14,$I$5:$I$6))) -> 2 | H14: 100
B15: 1.3 | C15: 화면 흐름 및 UI/UX 와이어프레임 설계 | D15: 김영석, 이준희 | E15: 46296 | F15: 46303 | G15: =IF(OR(E15="",F15=""),"",IF(F15<E15,"날짜 확인",NETWORKDAYS(E15,F15,$I$5:$I$6))) -> 5 | H15: 100
B16: 1.4 | C16: 수자원공사 규정·AI 학습자료 조사 | D16: 이준희, 오호민 | E16: 46296 | F16: 46303 | G16: =IF(OR(E16="",F16=""),"",IF(F16<E16,"날짜 확인",NETWORKDAYS(E16,F16,$I$5:$I$6))) -> 5 | H16: 100
B17: 2 | C17: 개발 착수 및 저장소 구축 | D17: - | E17: 46301 | F17: 46311 | G17: =IF(OR(E17="",F17=""),"",IF(F17<E17,"날짜 확인",NETWORKDAYS(E17,F17,$I$5:$I$6))) -> 8 | H17: =AVERAGE(H18:H22) -> 32
B18: 2.1 | C18: Git 저장소 및 소통 DM, 노션 생성 | D18: 송지섭 | E18: 46301 | F18: 46301 | G18: =IF(OR(E18="",F18=""),"",IF(F18<E18,"날짜 확인",NETWORKDAYS(E18,F18,$I$5:$I$6))) -> 1 | H18: 100
B19: 2.2 | C19: 점검·로드맵·교육 DB 및 ERD 설계 | D19: 오호민, 신가을 | E19: 46301 | F19: 46309 | G19: =IF(OR(E19="",F19=""),"",IF(F19<E19,"날짜 확인",NETWORKDAYS(E19,F19,$I$5:$I$6))) -> 6 | H19: 40
B20: 2.3 | C20: 규정·학습자료 전처리 및 청킹 | D20: 송지섭, 신가을 | E20: 46307 | F20: 46310 | G20: =IF(OR(E20="",F20=""),"",IF(F20<E20,"날짜 확인",NETWORKDAYS(E20,F20,$I$5:$I$6))) -> 4 | H20: 20
B21: 2.4 | C21: 요청 3분류 데이터셋 구축·분할 | D21: 이준희 | E21: 46308 | F21: 46310 | G21: =IF(OR(E21="",F21=""),"",IF(F21<E21,"날짜 확인",NETWORKDAYS(E21,F21,$I$5:$I$6))) -> 3 | H21: 0
B22: 2.5 | C22: 중간발표 자료 작성 및 발표 준비 | D22: 김영석 | E22: 46307 | F22: 46311 | G22: =IF(OR(E22="",F22=""),"",IF(F22<E22,"날짜 확인",NETWORKDAYS(E22,F22,$I$5:$I$6))) -> 5 | H22: 0
B23: 3 | C23: 모델 개발 및 RAG 구축 | D23: - | E23: 46314 | F23: 46318 | G23: =IF(OR(E23="",F23=""),"",IF(F23<E23,"날짜 확인",NETWORKDAYS(E23,F23,$I$5:$I$6))) -> 5 | H23: =AVERAGE(H24:H27) -> 0
B24: 3.1 | C24: 요청 분류 ML/DL 2종 학습·비교 | D24: 김영석 | E24: 46314 | F24: 46317 | G24: =IF(OR(E24="",F24=""),"",IF(F24<E24,"날짜 확인",NETWORKDAYS(E24,F24,$I$5:$I$6))) -> 4 | H24: 0
B25: 3.2 | C25: 규정·학습자료 색인 및 권한 필터 | D25: 송지섭 | E25: 46314 | F25: 46317 | G25: =IF(OR(E25="",F25=""),"",IF(F25<E25,"날짜 확인",NETWORKDAYS(E25,F25,$I$5:$I$6))) -> 4 | H25: 0
B26: 3.3 | C26: K-MOOC 연동 및 학습자료 DB 구축 | D26: 오호민 | E26: 46315 | F26: 46318 | G26: =IF(OR(E26="",F26=""),"",IF(F26<E26,"날짜 확인",NETWORKDAYS(E26,F26,$I$5:$I$6))) -> 4 | H26: 0
B27: 3.4 | C27: RDB 구축·직원/상급자 가상자료 적재 | D27: [미정] | E27: 46315 | F27: 46318 | G27: =IF(OR(E27="",F27=""),"",IF(F27<E27,"날짜 확인",NETWORKDAYS(E27,F27,$I$5:$I$6))) -> 4 | H27: 0
B28: 4 | C28: 에이전트 및 sLLM 구현 | D28: - | E28: 46321 | F28: 46325 | G28: =IF(OR(E28="",F28=""),"",IF(F28<E28,"날짜 확인",NETWORKDAYS(E28,F28,$I$5:$I$6))) -> 5 | H28: =AVERAGE(H29:H34) -> 0
B29: 4.1 | C29: sLLM 데이터·고정 시험 30건 준비 | D29: [미정] | E29: 46321 | F29: 46323 | G29: =IF(OR(E29="",F29=""),"",IF(F29<E29,"날짜 확인",NETWORKDAYS(E29,F29,$I$5:$I$6))) -> 3 | H29: 0
B30: 4.2 | C30: 규정 에이전트·챗봇 라우팅 구현 | D30: 이준희 | E30: 46321 | F30: 46324 | G30: =IF(OR(E30="",F30=""),"",IF(F30<E30,"날짜 확인",NETWORKDAYS(E30,F30,$I$5:$I$6))) -> 4 | H30: 0
B31: 4.3 | C31: 로드맵 계획·관점별 3안 구현 | D31: 오호민, 김영석 | E31: 46322 | F31: 46325 | G31: =IF(OR(E31="",F31=""),"",IF(F31<E31,"날짜 확인",NETWORKDAYS(E31,F31,$I$5:$I$6))) -> 4 | H31: 0
B32: 4.4 | C32: sLLM 요건 확인·LoRA/QLoRA 학습/서빙 | D32: 오호민, 김영석 | E32: 46323 | F32: 46325 | G32: =IF(OR(E32="",F32=""),"",IF(F32<E32,"날짜 확인",NETWORKDAYS(E32,F32,$I$5:$I$6))) -> 3 | H32: 0
B33: 4.5 | C33: 진단 에이전트·점검/결과 보고 구현 | D33: 이준희 | E33: 46323 | F33: 46325 | G33: =IF(OR(E33="",F33=""),"",IF(F33<E33,"날짜 확인",NETWORKDAYS(E33,F33,$I$5:$I$6))) -> 3 | H33: 0
B34: 4.6 | C34: 공통 검사·확정/저장·자료 운영 | D34: [미정] | E34: 46324 | F34: 46325 | G34: =IF(OR(E34="",F34=""),"",IF(F34<E34,"날짜 확인",NETWORKDAYS(E34,F34,$I$5:$I$6))) -> 2 | H34: 0
B35: 5 | C35: 비교 실험 및 기능 동결 | D35: - | E35: 46328 | F35: 46332 | G35: =IF(OR(E35="",F35=""),"",IF(F35<E35,"날짜 확인",NETWORKDAYS(E35,F35,$I$5:$I$6))) -> 5 | H35: =AVERAGE(H36,H38:H39) -> 0
B36: 5.1 | C36: 구성·학습·후보 방식 비교(A/B/C/E/F/G) | D36: 송지섭 | E36: 46328 | F36: 46330 | G36: =IF(OR(E36="",F36=""),"",IF(F36<E36,"날짜 확인",NETWORKDAYS(E36,F36,$I$5:$I$6))) -> 3 | H36: 0
B37: 5.2 | C37: 모델 후보 비교(D, 선택 실험) | D37: [미정] | E37: 46329 | F37: 46331 | G37: =IF(OR(E37="",F37=""),"",IF(F37<E37,"날짜 확인",NETWORKDAYS(E37,F37,$I$5:$I$6))) -> 3 | H37: 0
B38: 5.3 | C38: 비교 분석·멀티에이전트 보고서 작성 | D38: 송지섭 | E38: 46330 | F38: 46332 | G38: =IF(OR(E38="",F38=""),"",IF(F38<E38,"날짜 확인",NETWORKDAYS(E38,F38,$I$5:$I$6))) -> 3 | H38: 0
B39: 5.4 | C39: 시스템 구성도·코드/기능·모델 동결 | D39: [미정] | E39: 46331 | F39: 46332 | G39: =IF(OR(E39="",F39=""),"",IF(F39<E39,"날짜 확인",NETWORKDAYS(E39,F39,$I$5:$I$6))) -> 2 | H39: 0
B40: 6 | C40: 통합 테스트 및 결함 개선 | D40: - | E40: 46335 | F40: 46339 | G40: =IF(OR(E40="",F40=""),"",IF(F40<E40,"날짜 확인",NETWORKDAYS(E40,F40,$I$5:$I$6))) -> 5 | H40: =AVERAGE(H41:H43) -> 0
B41: 6.1 | C41: 권한·세션·저장·공개 범위 테스트 | D41: [미정] | E41: 46335 | F41: 46337 | G41: =IF(OR(E41="",F41=""),"",IF(F41<E41,"날짜 확인",NETWORKDAYS(E41,F41,$I$5:$I$6))) -> 3 | H41: 0
B42: 6.2 | C42: 팀원 5명 사례·전 과정 흐름 검증 | D42: 송지섭 | E42: 46336 | F42: 46338 | G42: =IF(OR(E42="",F42=""),"",IF(F42<E42,"날짜 확인",NETWORKDAYS(E42,F42,$I$5:$I$6))) -> 3 | H42: 0
...

Sheet 작업 상세
A1: V13 작업 범위와 완료 기준
A2: 기준: (1007)HR_상담_성장지원_기획서_보완안_V13 | 2026.10.08 반영 | 기존 일정·담당·완료 상태 유지, 세부 기준·분담은 팀 검토 전
A4: WBS 번호 | B4: 작업명 | C4: 담당자 | D4: 수행 내용 | E4: 선행 조건 | F4: 완료 조건·산출물 | G4: 연결 요구사항 | H4: 검토자 | I4: 구분 | J4: 일정·협의 사항
A5: ='갠트 차트 템플릿'!B12 -> 1 | B5: ='갠트 차트 템플릿'!C12 -> 주제 확정 후 재기획 및 아키텍처 보완 | C5: ='갠트 차트 템플릿'!D12 -> 송지섭 | D5: 업무 AI 적용을 위한 학습 지원으로 대상·문제 가설·목적 정리. 1차·후속·제외 범위 조정과 역할별 기능·권한 검토. 메인 3개 구조·가상 기관 전환 여부 등 협의. | E5: V13 검토 | F5: 범위 조정 결과와 미정 항목을 기획서·요구사항·화면·WBS에 일치시키고 팀 검토 결과 기록. 미정 항목은 확인 담당·다음 확인 시점을 남김. | G5: FR-01, FR-10, FR-19, NFR-05 | H5: [미정] | I5: 기존 작업 / 추가 협의 | J5: 기존 9/28~10/8 재기획 작업에 범위 조정 포함. 최신 진행률은 간트 H열 기준. 문서 반영만으로 팀 검토 완료를 뜻하지 않음.
A6: ='갠트 차트 템플릿'!B13 -> 1.1 | B6: ='갠트 차트 템플릿'!C13 -> 도로공사서비스 규정 및 평가표 분석 | C6: ='갠트 차트 템플릿'!D13 -> 신가을 | D6: 한국도로공사서비스 규정·평가표의 기존 조사 이력 보존. 수자원공사 자료는 1.4 조사 후 2.3 전처리로 연결. | E6: 기존 조사 자료 | F6: 기존 조사 결과와 출처 확인. 기관 변경으로 완료 이력을 바꾸지 않음. | G6: FR-07, NFR-06 | H6: [미정] | I6: 기존 완료 이력 | J6: 기존 담당·일정·100% 유지.
A7: ='갠트 차트 템플릿'!B14 -> 1.2 | B7: ='갠트 차트 템플릿'!C14 -> 요구사항 정의서 및 WBS 작성 | C7: ='갠트 차트 템플릿'!D14 -> 오호민 | D7: V13에 따라 요구사항 ID·범위·검증 기준과 WBS 작업을 대조. 10/2 제출 이후 최신 내용 갱신. | E7: V13 검토 | F7: 대상·문제 가설·업무 활용 목적과 역할별 기능·권한 확인. 요구사항 누락·상충 점검 및 팀 검토. 파일 수정만으로 검토 완료 처리하지 않음. | G7: 전체 요구사항 | H7: [미정] | I7: 기존 작업 / 최신화 | J7: 기존 제출 일정·진행률 보존. V13 반영 확인은 별도 검토.
A8: ='갠트 차트 템플릿'!B15 -> 1.3 | B8: ='갠트 차트 템플릿'!C15 -> 화면 흐름 및 UI/UX 와이어프레임 설계 | C8: ='갠트 차트 템플릿'!D15 -> 김영석, 이준희 | D8: 목표·설문·시작점·3안 비교·선택·수정안 확인·확정·실행·결과 보고서·챗봇·상급자·관리 화면 설계. | E8: 요구사항·권한 기본안 | F8: 주요 화면과 상태·정상/예외 흐름을 연결한 화면 설계서. | G8: FR-05, FR-06, FR-09, FR-12, FR-14, FR-15, FR-17~FR-20 | H8: [미정] | I8: 1차 | J8: 10/8 화면 설계서. 세부 권한 미정 부분 명시.
A9: ='갠트 차트 템플릿'!B16 -> 1.4 | B9: ='갠트 차트 템플릿'!C16 -> 수자원공사 규정·AI 학습자료 조사 | C9: ='갠트 차트 템플릿'!D16 -> 이준희, 오호민 | D9: 수자원공사 교육 관련 규정·AI 학습자료 조사. 개발/운영 적용 대상·선수지식·시간·비용·출처·이용 조건과 역량 매핑 정리. | E9: 첫 시연 목표·확보 규정 | F9: 수집 데이터 보고서·학습자료 목록·매핑표·규정 근거표·미확보 목록. | G9: FR-02, FR-03, FR-07, FR-08, NFR-06 | H9: [미정] | I9: 1차 / 추가 연동 조건부 | J9: 10/8 수집 보고서. 최신 진행률은 간트 H열 기준. 확보·미확보를 구분.
A10: ='갠트 차트 템플릿'!B18 -> 2.1 | B10: ='갠트 차트 템플릿'!C18 -> Git 저장소 및 소통 DM, 노션 생성 | C10: ='갠트 차트 템플릿'!D18 -> 송지섭 | D10: 기존 Git 저장소·Notion·소통 경로 준비 이력 유지. 실제 팀 저장소 경로와 운영 규칙 확인. | E10: 기존 환경 | F10: 기존 생성 결과·접근 확인 근거 보존. | G10: NFR-02, NFR-06 | H10: [미정] | I10: 기존 완료 이력 | J10: 기존 10/6·100% 유지. 비밀키·개인 자료·가중치는 Git 제외.
A11: ='갠트 차트 템플릿'!B19 -> 2.2 | B11: ='갠트 차트 템플릿'!C19 -> 점검·로드맵·교육 DB 및 ERD 설계 | C11: ='갠트 차트 템플릿'!D19 -> 오호민, 신가을 | D11: 기관/사용자/자료와 설문·점수·후보·선택 결과·관점 버전·수정안·실행·보고서·상급자 코멘트 설계. 설문·권한 기준 협의 포함. | E11: 1.2·1.3·1.4, 설문·권한 기준 | F11: ERD·데이터 정의서·공통 입출력 예시. 개인 기록과 벡터 색인 분리. | G11: FR-01, FR-06, FR-09, FR-12, FR-14, FR-15, FR-17~FR-19, NFR-02, NFR-06 | H11: [미정] | I11: 1차 | J11: 기존 10/14 설계 완료 목표, 10/16 DB 설계 문서 제출. 기준 확정이 선행.
A12: ='갠트 차트 템플릿'!B20 -> 2.3 | B12: ='갠트 차트 템플릿'!C20 -> 규정·학습자료 전처리 및 청킹 | C12: ='갠트 차트 템플릿'!D20 -> 송지섭, 신가을 | D12: 수자원공사 규정·학습자료 전처리와 청킹. 문서/조항 ID·시행일·적용 대상·원문 위치와 처리 기준 정리. | E12: 1.4 조사 목록·2.2 데이터 설계 | F12: 전처리 결과서·규정 메타데이터·청킹 결과. 미확보·불명확 근거는 확인 필요로 기록. | G12: FR-06, FR-07, FR-08, FR-13, NFR-06 | H12: [미정] | I12: 1차 | J12: 10/15 내부 목표·10/16 전처리 결과서. 규정 자동 수집 제외.
A13: ='갠트 차트 템플릿'!B21 -> 2.4 | B13: ='갠트 차트 템플릿'!C21 -> 요청 3분류 데이터셋 구축·분할 | C13: ='갠트 차트 템플릿'!D21 -> 이준희 | D13: 규정·일반·범위 밖(승진·발령·보수·성과급 상담) 질문과 불확실 요청 사례 작성. 로드맵·점검 요청은 일반(메뉴 안내)으로 라벨. 유사 문장·파생 사례 분리. | E13: FR-20 분류 정의 | F13: 3분류 라벨 기준·데이터 버전·분할 기록과 예외 사례 확보. | G13: FR-20, NFR-01, NFR-06 | H13: [미정] | I13: 1차 | J13: 10/15 데이터 준비 후 3.1 모델 비교로 연결.
A14: ='갠트 차트 템플릿'!B22 -> 2.5 | B14: ='갠트 차트 템플릿'!C22 -> 중간발표 자료 작성 및 발표 준비 | C14: ='갠트 차트 템플릿'!D22 -> 김영석 | D14: 대상·문제 가설·데이터 확보 수준·화면·설계와 미정 항목 정리. | E14: 1.2·1.3·1.4, 2.2·2.3 | F14: 기획·설계·데이터 중심 중간발표 자료와 시연 범위. | G14: 전체 요구사항 | H14: [미정] | I14: 1차 | J14: V13 기준 중간발표 10/16. 구현 완료 발표로 표현하지 않음.
A15: ='갠트 차트 템플릿'!B24 -> 3.1 | B15: ='갠트 차트 템플릿'!C24 -> 요청 분류 ML/DL 2종 학습·비교 | C15: ='갠트 차트 템플릿'!D24 -> 김영석 | D15: TF-IDF+로지스틱 회귀와 한국어 사전학습 분류 모델을 같은 분할로 학습·평가. 불확실 요청 처리 기준 검토. | E15: 2.4 분류 데이터 | F15: macro-F1·유형별 F1·혼동 사례와 학습 모델 패키지. | G15: FR-20, NFR-01 | H15: [미정] | I15: 1차 | J15: 10/22 내부 목표·10/23 ML/DL 학습결과서 및 학습 모델.
A16: ='갠트 차트 템플릿'!B25 -> 3.2 | B16: ='갠트 차트 템플릿'!C25 -> 규정·학습자료 색인 및 권한 필터 | C16: ='갠트 차트 템플릿'!D25 -> 송지섭 | D16: 규정·외부 학습자료 벡터 색인과 기관/시점/권한 필터. 역량 매핑 우선 후 벡터 검색. 공통 검색 도구 연결. | E16: 2.2·2.3, 1.4 등록 가능한 목록 | F16: 색인 구축 결과서·근거 위치 조회·교차 기관/버전 혼입 방지. | G16: FR-01, FR-07, FR-08, NFR-06 | H16: [미정] | I16: 1차 | J16: 10/23 벡터DB 결과서. 3.3 완료 전에는 직접 확보한 검토 목록으로 구축.
A17: ='갠트 차트 템플릿'!B26 -> 3.3 | B17: ='갠트 차트 템플릿'!C26 -> K-MOOC 연동 및 학습자료 DB 구축 | C17: ='갠트 차트 템플릿'!D26 -> 오호민 | D17: K-MOOC 수집·정규화·중복 처리와 공식 문서 등록. KOHI 보완 및 GSEEK/정보나루/민간 자료의 승인·이용 조건 관리. | E17: 1.4 출처·이용 조건, 2.2 스키마 | F17: API 수집·실패 처리·DB 적재와 출처 메타데이터 대조. | G17: FR-02, FR-03, FR-08 | H17: [미정] | I17: 1차 / 추가 연동 조건부 | J17: 실제 RAG 학습자료 확보가 선행. 승인 전 추가 API 연동을 확정하지 않음.
A18: ='갠트 차트 템플릿'!B27 -> 3.4 | B18: ='갠트 차트 템플릿'!C27 -> RDB 구축·직원/상급자 가상자료 적재 | C18: ='갠트 차트 템플릿'!D27 -> [미정] | D18: 가상 직원 5명·상급자·설문 적재. 원문·관계형 데이터·벡터·체크포인트 저장 경계 구현. | E18: 2.2 설계·사례 생성 규칙 | F18: PK/FK·중복·결측·점수 범위 검사와 GPU 외부 저장 확인. | G18: FR-06, NFR-02, NFR-06 | H18: [미정] | I18: 1차 | J18: 실제/가상 출처 구분. 팀원 제공 정보는 동의 범위만 사용. DB 제품 미정.
A19: ='갠트 차트 템플릿'!B29 -> 4.1 | B19: ='갠트 차트 템플릿'!C29 -> sLLM 데이터·고정 시험 30건 준비 | C19: ='갠트 차트 템플릿'!D29 -> [미정] | D19: 후보 작성·수정 학습 사례와 고정 시험 30건 준비. 학습/검증/평가 분리, 프로그램 검사·사람 검토. 시험: 규정 8·점검 6·로드맵/수정 10·예외 6. | E19: 자체 sLLM 요건·출력 계약·검색 자료·관점 기준 | F19: 생성 규칙·검토 기록·분할·시험 기대 결과·평가표. 검증·평가 전수 검토, 검토자 2명은 지정 필요. | G19: FR-10, FR-11, FR-17, NFR-03, NFR-06, NFR-07 | H19: [미정] | I19: 1차 실험 / 규모 협의 | J19: 10/26~28에 생성·검토 집중. 300/50/50은 목표안. 최종 평가셋으로 튜닝하지 않음.
A20: ='갠트 차트 템플릿'!B30 -> 4.2 | B20: ='갠트 차트 템플릿'!C30 -> 규정 에이전트·챗봇 라우팅 구현 | C20: ='갠트 차트 템플릿'!D30 -> 이준희 | D20: 규정 에이전트·하단 챗봇과 요청 3분류 연결. 규정은 조항·적용 조건·한계 답변, 일반은 일반 답변 표시·메뉴 안내, 범위 밖은 답하지 않고 안내. 로드맵의 지원 조건 확인 요청에 결과 반환. | E20: 3.1 분류·3.2 검색·규정 근거표·진행 상태 계약 | F20: 규정·일반·범위 밖 경로, 불확실 질문 확인과 근거 부족 안내. 지원 조건 결과가 계획 작성으로 복귀. | G20: FR-07, FR-13, FR-20, NFR-01, NFR-05 | H20: [미정] | I20: 1차 | J20: 10/26~29. 분류·호출·대기·재개는 LangGraph, 별도 LLM 슈퍼바이저 없음.
A21: ='갠트 차트 템플릿'!B31 -> 4.3 | B21: ='갠트 차트 템플릿'!C31 -> 로드맵 계획·관점별 3안 구현 | C21: ='갠트 차트 템플릿'!D31 -> 오호민, 김영석 | D21: 로드맵 계획 에이전트와 관점별 후보 3개 구현. 비교 보고서·선택 결과 기록·선택 관점의 부분 수정 화면/API 연결. | E21: 목표·시작점 계약, 3.2~3.4, 관점·출력 기준 | F21: 같은 목표·한도 아래 3안 비교. 요청 부분만 수정하고 유지 조건 보존. 4.6의 사용자 확정·저장으로 연결. | G21: FR-02, FR-05, FR-08, FR-10, FR-15, FR-17, NFR-05 | H21: [미정] | I21: 1차 / 관점 기준 협의 | J21: 10/27~30. 설문·진단 출력은 4.5와 공통 계약으로 병행 개발.
A22: ='갠트 차트 템플릿'!B32 -> 4.4 | B22: ='갠트 차트 템플릿'!C32 -> sLLM 요건 확인·LoRA/QLoRA 학습/서빙 | C22: ='갠트 차트 템플릿'!D32 -> 오호민, 김영석 | D22: Qwen3.5-9B+LoRA 또는 QLoRA(실험 G에서 비교)와 RunPod A40 1장 우선 검토. 후보 작성/수정 학습 후 관점별 하위 에이전트가 어댑터 하나를 공유하고, 관점별 어댑터와 비교(실험 F). | E22: 자체 sLLM 요건·GPU 예산, 4.1 검토 데이터·출력 계약 | F22: 학습 실행 근거·어댑터·설정·소스·비용 기록과 추론 연결. 학습 전후 비교는 5.1. | G22: NFR-02, NFR-03 | H22: [미정] | I22: 1차 실험 / 환경 협의 | J22: 10/30 학습 완료 목표. 결과는 6주 멀티 에이전트 테스트 보고서의 sLLM 파인튜닝 평가(필요시)로 보고. 대표 길이·배치의 메모리 적합성을 확인한 뒤 실행.
A23: ='갠트 차트 템플릿'!B33 -> 4.5 | B23: ='갠트 차트 템플릿'!C33 -> 진단 에이전트·점검/결과 보고 구현 | C23: ='갠트 차트 템플릿'!D33 -> 이준희 | D23: 진단 에이전트의 개인별 사전 문항 생성(사후 같은 문항 재사용), 시작점 제안, 실행 기록·결과 보고서 구현. 점수 계산은 프로그램(화면 비표시), 설명·보완 방향은 에이전트 담당. | E23: 문항 수·생성 규칙·점수 기준, 3.4 저장소·확정 계획 계약 | F23: 생성 문항 검사·사후 같은 문항 재사용, 응답·계산·보고서 일치. 시작점 조정과 사용자 결과 확인. 사전 응답 부재 시 전후 차이 제외, 선택 첨부 없어도 기록 가능. | G23: FR-05, FR-12, FR-14, FR-18 | H23: [미정] | I23: 1차 / 설문 기준 협의 | J23: 10/28~30. 자기평가 변화와 실제 역량 향상 구분. 증빙 미제출을 미수행으로 판정하지 않음.
A24: ='갠트 차트 템플릿'!B34 -> 4.6 | B24: ='갠트 차트 템플릿'!C34 -> 공통 검사·확정/저장·자료 운영 | C24: ='갠트 차트 템플릿'!D34 -> [미정] | D24: 권한·형식·자료 ID·시간/예산 검사, 사용자 확인·확정·저장·복구. 자료 등록·버전 관리, 상급자 열람/코멘트와 아키텍처 문서 연결. | E24: 3.4 저장소, 4.2·4.3·4.5 출력 계약, 권한·재작성 기준 | F24: 확정 전 원본 유지·버전 재조회·실패 사유 기록. 규정 원문 대조·버전 운영·권한 검사. 10/30 AI 시스템 아키텍처. | G24: FR-01, FR-04, FR-06, FR-09, FR-11, FR-19, NFR-02, NFR-05, NFR-06 | H24: [미정] | I24: 1차 / 세부 분담 필요 | J24: 현재 간트 일정 10/29~10/30. 세부 분담·선행 착수 필요 여부는 팀 검토 후 간트·설명에 함께 반영. 재작성 기준·상급자 공개 범위·부서 집계 미정.
A25: ='갠트 차트 템플릿'!B36 -> 5.1 | B25: ='갠트 차트 템플릿'!C36 -> 구성·학습·후보 방식 비교(A/B/C/E/F/G) | C25: ='갠트 차트 템플릿'!D36 -> 송지섭 | D25: A 단일/B 메인 3개, B/C 어댑터 유무, E 1회 3안/관점별 병렬 작성, F 관점 설정(프롬프트)/관점별 어댑터, G LoRA/QLoRA 비교. | E25: 4.1 고정 평가 기준·4.2~4.6 연동본 | F25: 동일 입력·자료·도구·설정의 품질·위반·요청 밖 변경·처리 시간과 최초/보완 후 결과. | G25: NFR-03, NFR-04, NFR-07 | H25: [미정] | I25: 1차 | J25: 최종 평가 세트·사용 시점 기록. 처리 시간 개선이나 파인튜닝 향상을 가정하지 않음.
A26: ='갠트 차트 템플릿'!B37 -> 5.2 | B26: ='갠트 차트 템플릿'!C37 -> 모델 후보 비교(D, 선택 실험) | C26: ='갠트 차트 템플릿'!D37 -> [미정] | D26: 27B급 및 50~70B급 후보의 작성 품질·시간 비교. 27B LoRA는 별도 선택 실험. | E26: 필수 A/B/C/E/F/G 실험·GPU 예산·시간 확보 | F26: 실행한 경우 모델/양자화/환경·비용·결과 보고. 세대·크기 등 달라진 조건을 함께 설명. | G26: NFR-03, NFR-07 | H26: [미정] | I26: 선택 실험 | J26: 11/3~5는 선택 실험 가능 구간. 미실행을 필수 기능 미완료로 계산하지 않음.
A27: ='갠트 차트 템플릿'!B38 -> 5.3 | B27: ='갠트 차트 템플릿'!C38 -> 비교 분석·멀티에이전트 보고서 작성 | C27: ='갠트 차트 템플릿'!D38 -> 송지섭 | D27: 근거 적합성·정상 완료율·유용성·위반·처리 시간 분석. 미달·한계와 후속 개선 구분. | E27: 5.1, 5.2 실행 시 결과 | F27: 11/6 멀티에이전트 테스트 보고서. 목표값과 측정값을 구분. | G27: FR-11, NFR-04, NFR-07 | H27: [미정] | I27: 1차 | J27: 0건/90%/4점은 팀 검토용 목표. 실측으로 달성 여부 판단.
A28: ='갠트 차트 템플릿'!B39 -> 5.4 | B28: ='갠트 차트 템플릿'!C39 -> 시스템 구성도·코드/기능·모델 동결 | C28: ='갠트 차트 템플릿'!D39 -> [미정] | D28: 검증된 기능·모델·데이터·프롬프트·관점 버전 고정. 후속 기능·미정 항목 분리. | E28: 5.1·5.3, 주요 실패 해결 | F28: 11/6 시스템 구성도와 기능·모델 동결 기록. | G28: NFR-05, NFR-06, NFR-07 | H28: [미정] | I28: 1차 | J28: 선택 실험 결과 유무가 동결의 필수 전제가 되지 않음.
A29: ='갠트 차트 템플릿'!B41 -> 6.1 | B29: ='갠트 차트 템플릿'!C41 -> 권한·세션·저장·공개 범위 테스트 | C29: ='갠트 차트 템플릿'!D41 -> [미정] | D29: 권한 밖 자료·기관/버전 혼입·확정 전 덮어쓰기·GPU 재시작·자료 부족·근거 부족·상급자 비공개 항목 테스트. | E29: 5.4 동결본·권한표 | F29: 정상/실패/경계 결과와 결함 기록. 타인 노출·허위 자료·승인 오표시 점검. | G29: FR-01, FR-09, FR-11, FR-13, FR-19, NFR-02, NFR-06 | H29: [미정] | I29: 1차 | J29: 개인 기록 없는 것을 미수행·의지 부족으로 해석하지 않는 사례 포함.
A30: ='갠트 차트 템플릿'!B42 -> 6.2 | B30: ='갠트 차트 템플릿'!C42 -> 팀원 5명 사례·전 과정 흐름 검증 | C30: ='갠트 차트 템플릿'!D42 -> 송지섭 | D30: 가상 직원 5명 사례로 전체 흐름·사용자 선택·부분 수정·상급자 의견 반영 요청·결과 확인 검증. | E30: 5.4 동결본·시험 사례 | F30: 완료율·유용성 평가·불필요한 유보와 막힌 단계 기록. | G30: FR-05, FR-09, FR-12, FR-14, FR-15, FR-17~FR-20, NFR-07 | H30: [미정] | I30: 1차 | J30: 외부 대리 사용자 참여는 확정하지 않음. 자기평가 변화와 실제 역량 향상 구분.
A31: ='갠트 차트 템플릿'!B43 -> 6.3 | B31: ='갠트 차트 템플릿'!C43 -> 결함·예외 보강 및 서비스 시험 보고 | C31: ='갠트 차트 템플릿'!D43 -> [미정] | D31: 통합 시험 결함 수정과 영향 범위 재검증. 서비스 테스트 결과와 남은 제한 정리. | E31: 6.1·6.2 결함 | F31: 11/13 서비스 테스트 보고서·재검증 근거. | G31: NFR-07 | H31: [미정] | I31: 1차 | J31: 동결 후 범위 추가는 별도 협의. 결함 해결과 추가 기능을 구분.
A32: ='갠트 차트 템플릿'!B45 -> 7.1 | B32: ='갠트 차트 템플릿'!C45 -> 최종 웹 어플리케이션 배포 환경 점검 | C32: ='갠트 차트 템플릿'!D45 -> [미정] | D32: 웹 애플리케이션 실행·권한·저장·복구·환경 설정·배포 상태 확인. | E32: 6.3 검증본 | F32: 11/20 제출 가능한 웹 앱과 실행 안내. 비밀키·개인 정보 미노출 확인. | G32: FR-01, NFR-02, NFR-06 | H32: [미정] | I32: 1차 | J32: 배포 완료 여부는 실제 실행으로 확인.
A33: ='갠트 차트 템플릿'!B46 -> 7.2 | B33: ='갠트 차트 템플릿'!C46 -> 최종 보고서 작성 및 GitHub 코드 정리 | C33: ='갠트 차트 템플릿'!D46 -> [미정] | D33: 최종 산출물과 실행법·설계·실험·한계를 정리. 코드와 대용량 외부 산출물 위치·버전 연결. | E33: 6.3, 5.3 실험 보고서 | F33: 최종 보고서·소스코드·모델/데이터 manifest와 링크 확인. | G33: NFR-02, NFR-06, NFR-07 | H33: [미정] | I33: 1차 | J33: 11/20 최종 제출. Git 커밋·푸시는 별도 승인과 팀 절차 적용.
A34: ='갠트 차트 템플릿'!B47 -> 7.3 | B34: ='갠트 차트 템플릿'!C47 -> 시연 시나리오 3종 영상 녹화 및 편집 | C34: ='갠트 차트 템플릿'!D47 -> [미정] | D34: 규정 상담, 후보 비교·선택·수정·확정, 실행·사후 점검·결과 보고서 시연. 첫 시연은 가상 개발/운영 직원의 RAG 학습. | E34: 6.3·7.1, 고정 시연 자료 | F34: 실제 모델 추론과 가상 데이터 사용 범위를 구분한 시연 영상. | G34: FR-07, FR-09, FR-10, FR-12, FR-14, FR-15, FR-17~FR-20 | H34: [미정] | I34: 1차 | J34: 팀원이 직접 만든 RAG 시제품을 서비스가 자동 제작한다고 표현하지 않음.
A35: ='갠트 차트 템플릿'!B48 -> 7.4 | B35: ='갠트 차트 템플릿'!C48 -> 최종 발표 자료 작성 및 발표 리허설 | C35: ='갠트 차트 템플릿'!D48 -> [미정] | D35: 문제·대상·설계·데이터·모델·검증 결과와 남은 과제 발표. 역할별 설명과 시연 점검. | E35: 7.1~7.3 | F35: 11/20 최종 발표·시연영상·웹 앱·소스 제출 확인. | G35: 전체 요구사항 | H35: [미정] | I35: 1차 | J35: 실측 근거와 팀 검토 후 제출. AI 작성만으로 사람 검토 완료 표시 금지.
A37: 4단계 세부 분담안 · 아래 항목은 기존 작업의 구성 내용이며 별도 확정된 WBS 번호가 아님
A38: 4.2 | B38: 규정 상담·챗봇 | C38: 이준희 | D38: 근거 답변·지원 조건 확인·요청 분기·확인 대기/재개. | E38: 규정 근거표·분류 모델·상태 계약 | F38: 불명확 질문 안내, 근거 부족 표시, 지원 조건이 계획 작성으로 복귀. | G38: FR-07, FR-13, FR-20 | H38: [미정] | I38: 1차 / 분담 필요 | J38: 재작성 횟수·중단 조건은 미정.
A39: 4.3 | B39: 후보 생성·비교 | C39: [미정] | D39: 같은 목표·한도에서 관점별 3안 작성·비교 보고서. | E39: 시작점·관점·검색 자료·출력 계약 | F39: 단계·기간·비용·장단점 비교, 미확인 지원과 실습 과제 구분. | G39: FR-02, FR-08, FR-10, FR-15, NFR-05 | H39: [미정] | I39: 1차 / 분담 필요 | J39: 관점 구성은 협의. 한 GPU의 속도 개선을 보장하지 않음.
A40: 4.3 | B40: 선택·부분 수정 | C40: 이준희 | D40: 선택 결과 기록, 선택 관점만 수정. | E40: 후보 ID·유지 조건 | F40: 요청 부분 수정·기존 조건 유지, 확인·확정 경로 연결. | G40: FR-09, FR-17 | H40: [미정] | I40: 1차 / 분담 필요 | J40: 작성 조건 변경·관점 교체는 후속.
A41: 4.5 | B41: 사전 점검·시작점 | C41: [미정] | D41: 목표·조건 입력과 학습 선호 대화, 개인별 문항 생성·응답, 점수 계산(화면 비표시)·시작점 제안·사용자 조정. | E41: 문항 수·생성 규칙·점수·시작점 기준 | F41: 생성 문항 검사, 응답·계산·요약 일치, 사용자 시작 단계 변경. | G41: FR-05, FR-14 | H41: [미정] | I41: 1차 / 기준 협의 | J41: 4.3과 공통 입출력 계약으로 병행 개발.
A42: 4.5 | B42: 실행 기록·사후 점검 | C42: 이준희 | D42: 체크리스트·메모·선택 첨부·화면 알림, 사후 설문·결과 보고. | E42: 확정 계획·동일 설문·기록 구조 | F42: 기록·계산·보고서 일치. 사전 응답 부재 처리와 사용자 결과 확인. | G42: FR-12, FR-18 | H42: [미정] | I42: 1차 / 분담 필요 | J42: 계산·저장은 프로그램. 증빙 미제출을 미수행으로 보지 않음.
...
